[2025-05-15T09:45:40.088+0000] {taskinstance.py:1087} INFO - Dependencies all met for <TaskInstance: load_sales_csv.load_csv scheduled__2023-03-15T00:00:00+00:00 [queued]>
[2025-05-15T09:45:40.231+0000] {taskinstance.py:1087} INFO - Dependencies all met for <TaskInstance: load_sales_csv.load_csv scheduled__2023-03-15T00:00:00+00:00 [queued]>
[2025-05-15T09:45:40.231+0000] {taskinstance.py:1283} INFO - 
--------------------------------------------------------------------------------
[2025-05-15T09:45:40.231+0000] {taskinstance.py:1284} INFO - Starting attempt 1 of 1
[2025-05-15T09:45:40.231+0000] {taskinstance.py:1285} INFO - 
--------------------------------------------------------------------------------
[2025-05-15T09:45:40.788+0000] {taskinstance.py:1304} INFO - Executing <Task(PythonOperator): load_csv> on 2023-03-15 00:00:00+00:00
[2025-05-15T09:45:40.841+0000] {standard_task_runner.py:55} INFO - Started process 675 to run task
[2025-05-15T09:45:40.889+0000] {standard_task_runner.py:82} INFO - Running: ['***', 'tasks', 'run', 'load_sales_csv', 'load_csv', 'scheduled__2023-03-15T00:00:00+00:00', '--job-id', '77', '--raw', '--subdir', 'DAGS_FOLDER/load_sales.py', '--cfg-path', '/tmp/tmp4lxotabd']
[2025-05-15T09:45:40.904+0000] {standard_task_runner.py:83} INFO - Job 77: Subtask load_csv
[2025-05-15T09:45:41.722+0000] {task_command.py:389} INFO - Running <TaskInstance: load_sales_csv.load_csv scheduled__2023-03-15T00:00:00+00:00 [running]> on host 1430ca430efd
[2025-05-15T09:45:43.062+0000] {taskinstance.py:1513} INFO - Exporting the following env vars:
AIRFLOW_CTX_DAG_OWNER=***
AIRFLOW_CTX_DAG_ID=load_sales_csv
AIRFLOW_CTX_TASK_ID=load_csv
AIRFLOW_CTX_EXECUTION_DATE=2023-03-15T00:00:00+00:00
AIRFLOW_CTX_TRY_NUMBER=1
AIRFLOW_CTX_DAG_RUN_ID=scheduled__2023-03-15T00:00:00+00:00
[2025-05-15T09:45:52.696+0000] {taskinstance.py:1772} ERROR - Task failed with exception
Traceback (most recent call last):
  File "/home/airflow/.local/lib/python3.7/site-packages/airflow/operators/python.py", line 175, in execute
    return_value = self.execute_callable()
  File "/home/airflow/.local/lib/python3.7/site-packages/airflow/operators/python.py", line 192, in execute_callable
    return self.python_callable(*self.op_args, **self.op_kwargs)
  File "/opt/airflow/dags/load_sales.py", line 10, in load_csv_to_postgres
    df.to_sql('raw_sales', engine, if_exists='replace', index=False)
  File "/home/airflow/.local/lib/python3.7/site-packages/pandas/core/generic.py", line 2882, in to_sql
    method=method,
  File "/home/airflow/.local/lib/python3.7/site-packages/pandas/io/sql.py", line 728, in to_sql
    **engine_kwargs,
  File "/home/airflow/.local/lib/python3.7/site-packages/pandas/io/sql.py", line 1758, in to_sql
    dtype=dtype,
  File "/home/airflow/.local/lib/python3.7/site-packages/pandas/io/sql.py", line 1650, in prep_table
    table.create()
  File "/home/airflow/.local/lib/python3.7/site-packages/pandas/io/sql.py", line 860, in create
    self.pd_sql.drop_table(self.name, self.schema)
  File "/home/airflow/.local/lib/python3.7/site-packages/pandas/io/sql.py", line 1809, in drop_table
    self.meta.reflect(only=[table_name], schema=schema)
  File "/home/airflow/.local/lib/python3.7/site-packages/sqlalchemy/sql/schema.py", line 4901, in reflect
    Table(name, self, **reflect_opts)
  File "<string>", line 2, in __new__
  File "/home/airflow/.local/lib/python3.7/site-packages/sqlalchemy/util/deprecations.py", line 309, in warned
    return fn(*args, **kwargs)
  File "/home/airflow/.local/lib/python3.7/site-packages/sqlalchemy/sql/schema.py", line 619, in __new__
    metadata._remove_table(name, schema)
  File "/home/airflow/.local/lib/python3.7/site-packages/sqlalchemy/util/langhelpers.py", line 72, in __exit__
    with_traceback=exc_tb,
  File "/home/airflow/.local/lib/python3.7/site-packages/sqlalchemy/util/compat.py", line 210, in raise_
    raise exception
  File "/home/airflow/.local/lib/python3.7/site-packages/sqlalchemy/sql/schema.py", line 614, in __new__
    table._init(name, metadata, *args, **kw)
  File "/home/airflow/.local/lib/python3.7/site-packages/sqlalchemy/sql/schema.py", line 694, in _init
    resolve_fks=resolve_fks,
  File "/home/airflow/.local/lib/python3.7/site-packages/sqlalchemy/sql/schema.py", line 729, in _autoload
    _extend_on=_extend_on,
  File "/home/airflow/.local/lib/python3.7/site-packages/sqlalchemy/engine/reflection.py", line 789, in reflect_table
    raise exc.NoSuchTableError(table_name)
sqlalchemy.exc.NoSuchTableError: raw_sales
[2025-05-15T09:45:52.788+0000] {taskinstance.py:1327} INFO - Marking task as FAILED. dag_id=load_sales_csv, task_id=load_csv, execution_date=20230315T000000, start_date=20250515T094540, end_date=20250515T094552
[2025-05-15T09:45:53.432+0000] {standard_task_runner.py:105} ERROR - Failed to execute job 77 for task load_csv (raw_sales; 675)
[2025-05-15T09:45:53.635+0000] {local_task_job.py:159} INFO - Task exited with return code 1
[2025-05-15T09:45:53.691+0000] {taskinstance.py:2582} INFO - 0 downstream tasks scheduled from follow-on schedule check
