[2025-05-15T09:40:07.685+0000] {taskinstance.py:1087} INFO - Dependencies all met for <TaskInstance: load_sales_csv.load_csv scheduled__2023-01-23T00:00:00+00:00 [queued]>
[2025-05-15T09:40:07.766+0000] {taskinstance.py:1087} INFO - Dependencies all met for <TaskInstance: load_sales_csv.load_csv scheduled__2023-01-23T00:00:00+00:00 [queued]>
[2025-05-15T09:40:07.771+0000] {taskinstance.py:1283} INFO - 
--------------------------------------------------------------------------------
[2025-05-15T09:40:07.772+0000] {taskinstance.py:1284} INFO - Starting attempt 1 of 1
[2025-05-15T09:40:07.772+0000] {taskinstance.py:1285} INFO - 
--------------------------------------------------------------------------------
[2025-05-15T09:40:08.010+0000] {taskinstance.py:1304} INFO - Executing <Task(PythonOperator): load_csv> on 2023-01-23 00:00:00+00:00
[2025-05-15T09:40:08.033+0000] {standard_task_runner.py:55} INFO - Started process 359 to run task
[2025-05-15T09:40:08.039+0000] {standard_task_runner.py:82} INFO - Running: ['***', 'tasks', 'run', 'load_sales_csv', 'load_csv', 'scheduled__2023-01-23T00:00:00+00:00', '--job-id', '26', '--raw', '--subdir', 'DAGS_FOLDER/load_sales.py', '--cfg-path', '/tmp/tmpke1171_j']
[2025-05-15T09:40:08.041+0000] {standard_task_runner.py:83} INFO - Job 26: Subtask load_csv
[2025-05-15T09:40:08.444+0000] {task_command.py:389} INFO - Running <TaskInstance: load_sales_csv.load_csv scheduled__2023-01-23T00:00:00+00:00 [running]> on host 1430ca430efd
[2025-05-15T09:40:11.257+0000] {taskinstance.py:1513} INFO - Exporting the following env vars:
AIRFLOW_CTX_DAG_OWNER=***
AIRFLOW_CTX_DAG_ID=load_sales_csv
AIRFLOW_CTX_TASK_ID=load_csv
AIRFLOW_CTX_EXECUTION_DATE=2023-01-23T00:00:00+00:00
AIRFLOW_CTX_TRY_NUMBER=1
AIRFLOW_CTX_DAG_RUN_ID=scheduled__2023-01-23T00:00:00+00:00
[2025-05-15T09:40:18.713+0000] {taskinstance.py:1772} ERROR - Task failed with exception
Traceback (most recent call last):
  File "/home/airflow/.local/lib/python3.7/site-packages/sqlalchemy/engine/base.py", line 1901, in _execute_context
    cursor, statement, parameters, context
  File "/home/airflow/.local/lib/python3.7/site-packages/sqlalchemy/engine/default.py", line 736, in do_execute
    cursor.execute(statement, parameters)
psycopg2.errors.UndefinedTable: table "raw_sales" does not exist


The above exception was the direct cause of the following exception:

Traceback (most recent call last):
  File "/home/airflow/.local/lib/python3.7/site-packages/airflow/operators/python.py", line 175, in execute
    return_value = self.execute_callable()
  File "/home/airflow/.local/lib/python3.7/site-packages/airflow/operators/python.py", line 192, in execute_callable
    return self.python_callable(*self.op_args, **self.op_kwargs)
  File "/opt/airflow/dags/load_sales.py", line 10, in load_csv_to_postgres
    df.to_sql('raw_sales', engine, if_exists='replace', index=False)
  File "/home/airflow/.local/lib/python3.7/site-packages/pandas/core/generic.py", line 2882, in to_sql
    method=method,
  File "/home/airflow/.local/lib/python3.7/site-packages/pandas/io/sql.py", line 728, in to_sql
    **engine_kwargs,
  File "/home/airflow/.local/lib/python3.7/site-packages/pandas/io/sql.py", line 1758, in to_sql
    dtype=dtype,
  File "/home/airflow/.local/lib/python3.7/site-packages/pandas/io/sql.py", line 1650, in prep_table
    table.create()
  File "/home/airflow/.local/lib/python3.7/site-packages/pandas/io/sql.py", line 860, in create
    self.pd_sql.drop_table(self.name, self.schema)
  File "/home/airflow/.local/lib/python3.7/site-packages/pandas/io/sql.py", line 1810, in drop_table
    self.get_table(table_name, schema).drop()
  File "/home/airflow/.local/lib/python3.7/site-packages/sqlalchemy/sql/schema.py", line 979, in drop
    bind._run_ddl_visitor(ddl.SchemaDropper, self, checkfirst=checkfirst)
  File "/home/airflow/.local/lib/python3.7/site-packages/sqlalchemy/engine/base.py", line 3228, in _run_ddl_visitor
    conn._run_ddl_visitor(visitorcallable, element, **kwargs)
  File "/home/airflow/.local/lib/python3.7/site-packages/sqlalchemy/engine/base.py", line 2211, in _run_ddl_visitor
    visitorcallable(self.dialect, self, **kwargs).traverse_single(element)
  File "/home/airflow/.local/lib/python3.7/site-packages/sqlalchemy/sql/visitors.py", line 524, in traverse_single
    return meth(obj, **kw)
  File "/home/airflow/.local/lib/python3.7/site-packages/sqlalchemy/sql/ddl.py", line 1102, in visit_table
    self.connection.execute(DropTable(table))
  File "/home/airflow/.local/lib/python3.7/site-packages/sqlalchemy/engine/base.py", line 1380, in execute
    return meth(self, multiparams, params, _EMPTY_EXECUTION_OPTS)
  File "/home/airflow/.local/lib/python3.7/site-packages/sqlalchemy/sql/ddl.py", line 81, in _execute_on_connection
    self, multiparams, params, execution_options
  File "/home/airflow/.local/lib/python3.7/site-packages/sqlalchemy/engine/base.py", line 1478, in _execute_ddl
    compiled,
  File "/home/airflow/.local/lib/python3.7/site-packages/sqlalchemy/engine/base.py", line 1944, in _execute_context
    e, statement, parameters, cursor, context
  File "/home/airflow/.local/lib/python3.7/site-packages/sqlalchemy/engine/base.py", line 2125, in _handle_dbapi_exception
    sqlalchemy_exception, with_traceback=exc_info[2], from_=e
  File "/home/airflow/.local/lib/python3.7/site-packages/sqlalchemy/util/compat.py", line 210, in raise_
    raise exception
  File "/home/airflow/.local/lib/python3.7/site-packages/sqlalchemy/engine/base.py", line 1901, in _execute_context
    cursor, statement, parameters, context
  File "/home/airflow/.local/lib/python3.7/site-packages/sqlalchemy/engine/default.py", line 736, in do_execute
    cursor.execute(statement, parameters)
sqlalchemy.exc.ProgrammingError: (psycopg2.errors.UndefinedTable) table "raw_sales" does not exist

[SQL: 
DROP TABLE raw_sales]
(Background on this error at: https://sqlalche.me/e/14/f405)
[2025-05-15T09:40:18.906+0000] {taskinstance.py:1327} INFO - Marking task as FAILED. dag_id=load_sales_csv, task_id=load_csv, execution_date=20230123T000000, start_date=20250515T094007, end_date=20250515T094018
[2025-05-15T09:40:19.348+0000] {standard_task_runner.py:105} ERROR - Failed to execute job 26 for task load_csv ((psycopg2.errors.UndefinedTable) table "raw_sales" does not exist

[SQL: 
DROP TABLE raw_sales]
(Background on this error at: https://sqlalche.me/e/14/f405); 359)
[2025-05-15T09:40:19.537+0000] {local_task_job.py:159} INFO - Task exited with return code 1
[2025-05-15T09:40:19.643+0000] {taskinstance.py:2582} INFO - 0 downstream tasks scheduled from follow-on schedule check
