[2025-05-15T09:39:03.810+0000] {taskinstance.py:1087} INFO - Dependencies all met for <TaskInstance: load_sales_csv.load_csv scheduled__2023-01-01T00:00:00+00:00 [queued]>
[2025-05-15T09:39:03.883+0000] {taskinstance.py:1087} INFO - Dependencies all met for <TaskInstance: load_sales_csv.load_csv scheduled__2023-01-01T00:00:00+00:00 [queued]>
[2025-05-15T09:39:03.883+0000] {taskinstance.py:1283} INFO - 
--------------------------------------------------------------------------------
[2025-05-15T09:39:03.883+0000] {taskinstance.py:1284} INFO - Starting attempt 1 of 1
[2025-05-15T09:39:03.883+0000] {taskinstance.py:1285} INFO - 
--------------------------------------------------------------------------------
[2025-05-15T09:39:04.048+0000] {taskinstance.py:1304} INFO - Executing <Task(PythonOperator): load_csv> on 2023-01-01 00:00:00+00:00
[2025-05-15T09:39:04.090+0000] {standard_task_runner.py:55} INFO - Started process 281 to run task
[2025-05-15T09:39:04.125+0000] {standard_task_runner.py:82} INFO - Running: ['***', 'tasks', 'run', 'load_sales_csv', 'load_csv', 'scheduled__2023-01-01T00:00:00+00:00', '--job-id', '3', '--raw', '--subdir', 'DAGS_FOLDER/load_sales.py', '--cfg-path', '/tmp/tmpgtdpgxt5']
[2025-05-15T09:39:04.141+0000] {standard_task_runner.py:83} INFO - Job 3: Subtask load_csv
[2025-05-15T09:39:04.582+0000] {task_command.py:389} INFO - Running <TaskInstance: load_sales_csv.load_csv scheduled__2023-01-01T00:00:00+00:00 [running]> on host 1430ca430efd
[2025-05-15T09:39:07.088+0000] {taskinstance.py:1513} INFO - Exporting the following env vars:
AIRFLOW_CTX_DAG_OWNER=***
AIRFLOW_CTX_DAG_ID=load_sales_csv
AIRFLOW_CTX_TASK_ID=load_csv
AIRFLOW_CTX_EXECUTION_DATE=2023-01-01T00:00:00+00:00
AIRFLOW_CTX_TRY_NUMBER=1
AIRFLOW_CTX_DAG_RUN_ID=scheduled__2023-01-01T00:00:00+00:00
[2025-05-15T09:39:27.948+0000] {taskinstance.py:1483} ERROR - Received SIGTERM. Terminating subprocesses.
[2025-05-15T09:39:28.662+0000] {taskinstance.py:1772} ERROR - Task failed with exception
Traceback (most recent call last):
  File "/home/airflow/.local/lib/python3.7/site-packages/airflow/operators/python.py", line 175, in execute
    return_value = self.execute_callable()
  File "/home/airflow/.local/lib/python3.7/site-packages/airflow/operators/python.py", line 192, in execute_callable
    return self.python_callable(*self.op_args, **self.op_kwargs)
  File "/opt/airflow/dags/load_sales.py", line 10, in load_csv_to_postgres
    df.to_sql('raw_sales', engine, if_exists='replace', index=False)
  File "/home/airflow/.local/lib/python3.7/site-packages/pandas/core/generic.py", line 2882, in to_sql
    method=method,
  File "/home/airflow/.local/lib/python3.7/site-packages/pandas/io/sql.py", line 728, in to_sql
    **engine_kwargs,
  File "/home/airflow/.local/lib/python3.7/site-packages/pandas/io/sql.py", line 1770, in to_sql
    **engine_kwargs,
  File "/home/airflow/.local/lib/python3.7/site-packages/pandas/io/sql.py", line 1340, in insert_records
    table.insert(chunksize=chunksize, method=method)
  File "/home/airflow/.local/lib/python3.7/site-packages/pandas/io/sql.py", line 967, in insert
    exec_insert(conn, keys, chunk_iter)
  File "/home/airflow/.local/lib/python3.7/site-packages/pandas/io/sql.py", line 881, in _execute_insert
    data = [dict(zip(keys, row)) for row in data_iter]
  File "/home/airflow/.local/lib/python3.7/site-packages/pandas/io/sql.py", line 881, in <listcomp>
    data = [dict(zip(keys, row)) for row in data_iter]
  File "/home/airflow/.local/lib/python3.7/site-packages/airflow/models/taskinstance.py", line 1485, in signal_handler
    raise AirflowException("Task received SIGTERM signal")
airflow.exceptions.AirflowException: Task received SIGTERM signal
[2025-05-15T09:39:28.711+0000] {taskinstance.py:1327} INFO - Marking task as FAILED. dag_id=load_sales_csv, task_id=load_csv, execution_date=20230101T000000, start_date=20250515T093903, end_date=20250515T093928
[2025-05-15T09:39:28.851+0000] {standard_task_runner.py:105} ERROR - Failed to execute job 3 for task load_csv (Task received SIGTERM signal; 281)
[2025-05-15T09:39:29.197+0000] {local_task_job.py:159} INFO - Task exited with return code 1
[2025-05-15T09:39:29.322+0000] {taskinstance.py:2582} INFO - 0 downstream tasks scheduled from follow-on schedule check
